<robot name = "robot">
    <link name="0">
        <inertial>
            <origin xyz="0 0 3" rpy="0 0 0"/>
            <mass value="1" />
            <inertia ixx="100" ixy="0" ixz="0" iyy="100" iyz="0" izz="100" />
        </inertial>
        <visual>
            <origin xyz="0 0 3" rpy="0 0 0"/>
            <geometry>
                <box size="0.2618788017314734 0.6081011136874733 0.4116791042428367" />
            </geometry>
            <material name="Green">
                <color rgba="0 1.0 0 1.0"/>
            </material>
        </visual>
        <collision>
            <origin xyz="0 0 3" rpy="0 0 0"/>
            <geometry>
                <box size="0.2618788017314734 0.6081011136874733 0.4116791042428367" />
            </geometry>
        </collision>
    </link>
    <joint name="3_1" type="revolute">
       <parent link="3"/>
       <child  link="1"/>
       <origin rpy="0 0 0" xyz="0.3098882557962468 0.425025000357732 3.1799145411012315" />
     <axis xyz="0 1 0"/>
       <limit effort="0.0" lower="-3.14159" upper="3.14159" velocity="0.0"/>
    </joint>
    <link name="1">
        <inertial>
            <origin xyz="0 0 -0.3873736762862372" rpy="0 0 0"/>
            <mass value="1" />
            <inertia ixx="100" ixy="0" ixz="0" iyy="100" iyz="0" izz="100" />
        </inertial>
        <visual>
            <origin xyz="0 0 -0.3873736762862372" rpy="0 0 0"/>
            <geometry>
                <box size="0.8377323948639859 0.28887264951841884 0.7747473525724744" />
            </geometry>
            <material name="Cyan">
                <color rgba="0 1.0 1.0 1.0"/>
            </material>
        </visual>
        <collision>
            <origin xyz="0 0 -0.3873736762862372" rpy="0 0 0"/>
            <geometry>
                <box size="0.8377323948639859 0.28887264951841884 0.7747473525724744" />
            </geometry>
        </collision>
    </link>
    <joint name="3_2" type="revolute">
       <parent link="3"/>
       <child  link="2"/>
       <origin rpy="0 0 0" xyz="0.3098882557962468 1.275075001073196 3.1799145411012315" />
     <axis xyz="0 1 0"/>
       <limit effort="0.0" lower="-3.14159" upper="3.14159" velocity="0.0"/>
    </joint>
    <link name="2">
        <inertial>
            <origin xyz="0 0.4556332880421372 0" rpy="0 0 0"/>
            <mass value="1" />
            <inertia ixx="100" ixy="0" ixz="0" iyy="100" iyz="0" izz="100" />
        </inertial>
        <visual>
            <origin xyz="0 0.4556332880421372 0" rpy="0 0 0"/>
            <geometry>
                <box size="0.6197765115924936 0.9112665760842744 0.3085206598950495" />
            </geometry>
            <material name="Cyan">
                <color rgba="0 1.0 1.0 1.0"/>
            </material>
        </visual>
        <collision>
            <origin xyz="0 0.4556332880421372 0" rpy="0 0 0"/>
            <geometry>
                <box size="0.6197765115924936 0.9112665760842744 0.3085206598950495" />
            </geometry>
        </collision>
    </link>
    <joint name="2_3" type="revolute">
       <parent link="2"/>
       <child  link="3"/>
       <origin rpy="0 0 0" xyz="0.3098882557962468 2.1863415771574704 3.1799145411012315" />
     <axis xyz="1 0 0"/>
       <limit effort="0.0" lower="-3.14159" upper="3.14159" velocity="0.0"/>
    </joint>
    <link name="3">
        <inertial>
            <origin xyz="0 0.425025000357732 0" rpy="0 0 0"/>
            <mass value="1" />
            <inertia ixx="100" ixy="0" ixz="0" iyy="100" iyz="0" izz="100" />
        </inertial>
        <visual>
            <origin xyz="0 0.425025000357732 0" rpy="0 0 0"/>
            <geometry>
                <box size="0.5371141168447652 0.850050000715464 0.36037068193542293" />
            </geometry>
            <material name="Cyan">
                <color rgba="0 1.0 1.0 1.0"/>
            </material>
        </visual>
        <collision>
            <origin xyz="0 0.425025000357732 0" rpy="0 0 0"/>
            <geometry>
                <box size="0.5371141168447652 0.850050000715464 0.36037068193542293" />
            </geometry>
        </collision>
    </link>
</robot>