<robot name = "robot">
    <link name="0">
        <inertial>
            <origin xyz="0 0 0.75" rpy="0 0 0"/>
            <mass value="1" />
            <inertia ixx="100" ixy="0" ixz="0" iyy="100" iyz="0" izz="100" />
        </inertial>
        <visual>
            <origin xyz="0 0 0.75" rpy="0 0 0"/>
            <geometry>
                <box size="0.9652696173172592 0.6954605685304595 0.7207295517443372" />
            </geometry>
            <material name="Cyan">
                <color rgba="0 1.0 1.0 1.0"/>
            </material>
        </visual>
        <collision>
            <origin xyz="0 0 0.75" rpy="0 0 0"/>
            <geometry>
                <box size="0.9652696173172592 0.6954605685304595 0.7207295517443372" />
            </geometry>
        </collision>
    </link>
    <joint name="0_1" type="revolute">
       <parent link="0"/>
       <child  link="1"/>
       <origin rpy="0 0 0" xyz="0 -0.3477302842652297 0.75" />
     <axis xyz="0 0 1"/>
       <limit effort="0.0" lower="-3.14159" upper="3.14159" velocity="0.0"/>
    </joint>
    <link name="1">
        <inertial>
            <origin xyz="0 -0.7098444184628969 0" rpy="0 0 0"/>
            <mass value="1" />
            <inertia ixx="100" ixy="0" ixz="0" iyy="100" iyz="0" izz="100" />
        </inertial>
        <visual>
            <origin xyz="0 -0.7098444184628969 0" rpy="0 0 0"/>
            <geometry>
                <box size="0.9455081159323865 1.4196888369257938 1.127589207266347" />
            </geometry>
            <material name="Green">
                <color rgba="0 1.0 0 1.0"/>
            </material>
        </visual>
        <collision>
            <origin xyz="0 -0.7098444184628969 0" rpy="0 0 0"/>
            <geometry>
                <box size="0.9455081159323865 1.4196888369257938 1.127589207266347" />
            </geometry>
        </collision>
    </link>
    <joint name="1_2" type="revolute">
       <parent link="1"/>
       <child  link="2"/>
       <origin rpy="0 0 0" xyz="0 -1.4196888369257938 0" />
     <axis xyz="0 0 1"/>
       <limit effort="0.0" lower="-3.14159" upper="3.14159" velocity="0.0"/>
    </joint>
    <link name="2">
        <inertial>
            <origin xyz="0 -0.37654786756404596 0" rpy="0 0 0"/>
            <mass value="1" />
            <inertia ixx="100" ixy="0" ixz="0" iyy="100" iyz="0" izz="100" />
        </inertial>
        <visual>
            <origin xyz="0 -0.37654786756404596 0" rpy="0 0 0"/>
            <geometry>
                <box size="1.1459052916525136 0.7530957351280919 0.7022251485655074" />
            </geometry>
            <material name="Green">
                <color rgba="0 1.0 0 1.0"/>
            </material>
        </visual>
        <collision>
            <origin xyz="0 -0.37654786756404596 0" rpy="0 0 0"/>
            <geometry>
                <box size="1.1459052916525136 0.7530957351280919 0.7022251485655074" />
            </geometry>
        </collision>
    </link>
    <joint name="2_3" type="revolute">
       <parent link="2"/>
       <child  link="3"/>
       <origin rpy="0 0 0" xyz="0 -0.7530957351280919 0" />
     <axis xyz="0 1 0"/>
       <limit effort="0.0" lower="-3.14159" upper="3.14159" velocity="0.0"/>
    </joint>
    <link name="3">
        <inertial>
            <origin xyz="0 -0.6720854345466412 0" rpy="0 0 0"/>
            <mass value="1" />
            <inertia ixx="100" ixy="0" ixz="0" iyy="100" iyz="0" izz="100" />
        </inertial>
        <visual>
            <origin xyz="0 -0.6720854345466412 0" rpy="0 0 0"/>
            <geometry>
                <box size="0.5461502319422752 1.3441708690932823 0.5221573490079146" />
            </geometry>
            <material name="Green">
                <color rgba="0 1.0 0 1.0"/>
            </material>
        </visual>
        <collision>
            <origin xyz="0 -0.6720854345466412 0" rpy="0 0 0"/>
            <geometry>
                <box size="0.5461502319422752 1.3441708690932823 0.5221573490079146" />
            </geometry>
        </collision>
    </link>
</robot>