<robot name = "robot">
    <link name="Torso">
        <inertial>
            <origin xyz="0 0 0.75" rpy="0 0 0"/>
            <mass value="1" />
            <inertia ixx="100" ixy="0" ixz="0" iyy="100" iyz="0" izz="100" />
        </inertial>
        <visual>
            <origin xyz="0 0 0.75" rpy="0 0 0"/>
            <geometry>
                <box size="1 0.5 0.5" />
            </geometry>
            <material name="Cyan">
                <color rgba="0 1.0 1.0 1.0"/>
            </material>
        </visual>
        <collision>
            <origin xyz="0 0 0.75" rpy="0 0 0"/>
            <geometry>
                <box size="1 0.5 0.5" />
            </geometry>
        </collision>
    </link>
    <joint name="Torso_FrontLeft" type="revolute">
       <parent link="Torso"/>
       <child  link="FrontLeft"/>
       <origin rpy="0 0 0" xyz="-0.25 0.25 0.75" />
     <axis xyz="1 0 0"/>
       <limit effort="0.0" lower="-3.14159" upper="3.14159" velocity="0.0"/>
    </joint>
    <link name="FrontLeft">
        <inertial>
            <origin xyz="0 0.375 0" rpy="0 0 0"/>
            <mass value="1" />
            <inertia ixx="100" ixy="0" ixz="0" iyy="100" iyz="0" izz="100" />
        </inertial>
        <visual>
            <origin xyz="0 0.375 0" rpy="0 0 0"/>
            <geometry>
                <box size="0.2 0.75 0.2" />
            </geometry>
            <material name="Cyan">
                <color rgba="0 1.0 1.0 1.0"/>
            </material>
        </visual>
        <collision>
            <origin xyz="0 0.375 0" rpy="0 0 0"/>
            <geometry>
                <box size="0.2 0.75 0.2" />
            </geometry>
        </collision>
    </link>
    <joint name="FrontLeft_FLLower" type="revolute">
       <parent link="FrontLeft"/>
       <child  link="FLLower"/>
       <origin rpy="0 0 0" xyz="0 0.75 0" />
     <axis xyz="1 0 0"/>
       <limit effort="0.0" lower="-3.14159" upper="3.14159" velocity="0.0"/>
    </joint>
    <link name="FLLower">
        <inertial>
            <origin xyz="0 0 -0.375" rpy="0 0 0"/>
            <mass value="1" />
            <inertia ixx="100" ixy="0" ixz="0" iyy="100" iyz="0" izz="100" />
        </inertial>
        <visual>
            <origin xyz="0 0 -0.375" rpy="0 0 0"/>
            <geometry>
                <box size="0.2 0.2 0.75" />
            </geometry>
            <material name="Cyan">
                <color rgba="0 1.0 1.0 1.0"/>
            </material>
        </visual>
        <collision>
            <origin xyz="0 0 -0.375" rpy="0 0 0"/>
            <geometry>
                <box size="0.2 0.2 0.75" />
            </geometry>
        </collision>
    </link>
    <joint name="Torso_FrontRight" type="revolute">
       <parent link="Torso"/>
       <child  link="FrontRight"/>
       <origin rpy="0 0 0" xyz="0.25 0.25 0.75" />
     <axis xyz="1 0 0"/>
       <limit effort="0.0" lower="-3.14159" upper="3.14159" velocity="0.0"/>
    </joint>
    <link name="FrontRight">
        <inertial>
            <origin xyz="0 0.375 0" rpy="0 0 0"/>
            <mass value="1" />
            <inertia ixx="100" ixy="0" ixz="0" iyy="100" iyz="0" izz="100" />
        </inertial>
        <visual>
            <origin xyz="0 0.375 0" rpy="0 0 0"/>
            <geometry>
                <box size="0.2 0.75 0.2" />
            </geometry>
            <material name="Cyan">
                <color rgba="0 1.0 1.0 1.0"/>
            </material>
        </visual>
        <collision>
            <origin xyz="0 0.375 0" rpy="0 0 0"/>
            <geometry>
                <box size="0.2 0.75 0.2" />
            </geometry>
        </collision>
    </link>
    <joint name="FrontRight_FRLower" type="revolute">
       <parent link="FrontRight"/>
       <child  link="FRLower"/>
       <origin rpy="0 0 0" xyz="0 0.75 0" />
     <axis xyz="1 0 0"/>
       <limit effort="0.0" lower="-3.14159" upper="3.14159" velocity="0.0"/>
    </joint>
    <link name="FRLower">
        <inertial>
            <origin xyz="0 0 -0.375" rpy="0 0 0"/>
            <mass value="1" />
            <inertia ixx="100" ixy="0" ixz="0" iyy="100" iyz="0" izz="100" />
        </inertial>
        <visual>
            <origin xyz="0 0 -0.375" rpy="0 0 0"/>
            <geometry>
                <box size="0.2 0.2 0.75" />
            </geometry>
            <material name="Cyan">
                <color rgba="0 1.0 1.0 1.0"/>
            </material>
        </visual>
        <collision>
            <origin xyz="0 0 -0.375" rpy="0 0 0"/>
            <geometry>
                <box size="0.2 0.2 0.75" />
            </geometry>
        </collision>
    </link>
    <joint name="Torso_BackLeft" type="revolute">
       <parent link="Torso"/>
       <child  link="BackLeft"/>
       <origin rpy="0 0 0" xyz="-0.25 -0.25 0.75" />
     <axis xyz="1 0 0"/>
       <limit effort="0.0" lower="-3.14159" upper="3.14159" velocity="0.0"/>
    </joint>
    <link name="BackLeft">
        <inertial>
            <origin xyz="0 -0.375 0" rpy="0 0 0"/>
            <mass value="1" />
            <inertia ixx="100" ixy="0" ixz="0" iyy="100" iyz="0" izz="100" />
        </inertial>
        <visual>
            <origin xyz="0 -0.375 0" rpy="0 0 0"/>
            <geometry>
                <box size="0.2 0.75 0.2" />
            </geometry>
            <material name="Cyan">
                <color rgba="0 1.0 1.0 1.0"/>
            </material>
        </visual>
        <collision>
            <origin xyz="0 -0.375 0" rpy="0 0 0"/>
            <geometry>
                <box size="0.2 0.75 0.2" />
            </geometry>
        </collision>
    </link>
    <joint name="BackLeft_BLLower" type="revolute">
       <parent link="BackLeft"/>
       <child  link="BLLower"/>
       <origin rpy="0 0 0" xyz="0 -0.75 0" />
     <axis xyz="1 0 0"/>
       <limit effort="0.0" lower="-3.14159" upper="3.14159" velocity="0.0"/>
    </joint>
    <link name="BLLower">
        <inertial>
            <origin xyz="0 0 -0.375" rpy="0 0 0"/>
            <mass value="1" />
            <inertia ixx="100" ixy="0" ixz="0" iyy="100" iyz="0" izz="100" />
        </inertial>
        <visual>
            <origin xyz="0 0 -0.375" rpy="0 0 0"/>
            <geometry>
                <box size="0.2 0.2 0.75" />
            </geometry>
            <material name="Cyan">
                <color rgba="0 1.0 1.0 1.0"/>
            </material>
        </visual>
        <collision>
            <origin xyz="0 0 -0.375" rpy="0 0 0"/>
            <geometry>
                <box size="0.2 0.2 0.75" />
            </geometry>
        </collision>
    </link>
    <joint name="Torso_BackRight" type="revolute">
       <parent link="Torso"/>
       <child  link="BackRight"/>
       <origin rpy="0 0 0" xyz="0.25 -0.25 0.75" />
     <axis xyz="1 0 0"/>
       <limit effort="0.0" lower="-3.14159" upper="3.14159" velocity="0.0"/>
    </joint>
    <link name="BackRight">
        <inertial>
            <origin xyz="0 -0.375 0" rpy="0 0 0"/>
            <mass value="1" />
            <inertia ixx="100" ixy="0" ixz="0" iyy="100" iyz="0" izz="100" />
        </inertial>
        <visual>
            <origin xyz="0 -0.375 0" rpy="0 0 0"/>
            <geometry>
                <box size="0.2 0.75 0.2" />
            </geometry>
            <material name="Cyan">
                <color rgba="0 1.0 1.0 1.0"/>
            </material>
        </visual>
        <collision>
            <origin xyz="0 -0.375 0" rpy="0 0 0"/>
            <geometry>
                <box size="0.2 0.75 0.2" />
            </geometry>
        </collision>
    </link>
    <joint name="BackRight_BRLower" type="revolute">
       <parent link="BackRight"/>
       <child  link="BRLower"/>
       <origin rpy="0 0 0" xyz="0 -0.75 0" />
     <axis xyz="1 0 0"/>
       <limit effort="0.0" lower="-3.14159" upper="3.14159" velocity="0.0"/>
    </joint>
    <link name="BRLower">
        <inertial>
            <origin xyz="0 0 -0.375" rpy="0 0 0"/>
            <mass value="1" />
            <inertia ixx="100" ixy="0" ixz="0" iyy="100" iyz="0" izz="100" />
        </inertial>
        <visual>
            <origin xyz="0 0 -0.375" rpy="0 0 0"/>
            <geometry>
                <box size="0.2 0.2 0.75" />
            </geometry>
            <material name="Cyan">
                <color rgba="0 1.0 1.0 1.0"/>
            </material>
        </visual>
        <collision>
            <origin xyz="0 0 -0.375" rpy="0 0 0"/>
            <geometry>
                <box size="0.2 0.2 0.75" />
            </geometry>
        </collision>
    </link>
    <joint name="Torso_Left" type="revolute">
       <parent link="Torso"/>
       <child  link="Left"/>
       <origin rpy="0 0 0" xyz="-0.5 0 0.75" />
     <axis xyz="0 1 0"/>
       <limit effort="0.0" lower="-3.14159" upper="3.14159" velocity="0.0"/>
    </joint>
    <link name="Left">
        <inertial>
            <origin xyz="-0.375 0 0" rpy="0 0 0"/>
            <mass value="1" />
            <inertia ixx="100" ixy="0" ixz="0" iyy="100" iyz="0" izz="100" />
        </inertial>
        <visual>
            <origin xyz="-0.375 0 0" rpy="0 0 0"/>
            <geometry>
                <box size="0.75 0.2 0.2" />
            </geometry>
            <material name="Cyan">
                <color rgba="0 1.0 1.0 1.0"/>
            </material>
        </visual>
        <collision>
            <origin xyz="-0.375 0 0" rpy="0 0 0"/>
            <geometry>
                <box size="0.75 0.2 0.2" />
            </geometry>
        </collision>
    </link>
    <joint name="Left_LeftLower" type="revolute">
       <parent link="Left"/>
       <child  link="LeftLower"/>
       <origin rpy="0 0 0" xyz="-0.75 0 0" />
     <axis xyz="1 0 0"/>
       <limit effort="0.0" lower="-3.14159" upper="3.14159" velocity="0.0"/>
    </joint>
    <link name="LeftLower">
        <inertial>
            <origin xyz="0 0 -0.375" rpy="0 0 0"/>
            <mass value="1" />
            <inertia ixx="100" ixy="0" ixz="0" iyy="100" iyz="0" izz="100" />
        </inertial>
        <visual>
            <origin xyz="0 0 -0.375" rpy="0 0 0"/>
            <geometry>
                <box size="0.2 0.2 0.75" />
            </geometry>
            <material name="Cyan">
                <color rgba="0 1.0 1.0 1.0"/>
            </material>
        </visual>
        <collision>
            <origin xyz="0 0 -0.375" rpy="0 0 0"/>
            <geometry>
                <box size="0.2 0.2 0.75" />
            </geometry>
        </collision>
    </link>
    <joint name="Torso_Right" type="revolute">
       <parent link="Torso"/>
       <child  link="Right"/>
       <origin rpy="0 0 0" xyz="0.5 0 0.75" />
     <axis xyz="0 1 0"/>
       <limit effort="0.0" lower="-3.14159" upper="3.14159" velocity="0.0"/>
    </joint>
    <link name="Right">
        <inertial>
            <origin xyz="0.375 0 0" rpy="0 0 0"/>
            <mass value="1" />
            <inertia ixx="100" ixy="0" ixz="0" iyy="100" iyz="0" izz="100" />
        </inertial>
        <visual>
            <origin xyz="0.375 0 0" rpy="0 0 0"/>
            <geometry>
                <box size="0.75 0.2 0.2" />
            </geometry>
            <material name="Cyan">
                <color rgba="0 1.0 1.0 1.0"/>
            </material>
        </visual>
        <collision>
            <origin xyz="0.375 0 0" rpy="0 0 0"/>
            <geometry>
                <box size="0.75 0.2 0.2" />
            </geometry>
        </collision>
    </link>
    <joint name="Right_RightLower" type="revolute">
       <parent link="Right"/>
       <child  link="RightLower"/>
       <origin rpy="0 0 0" xyz="0.75 0 0" />
     <axis xyz="1 0 0"/>
       <limit effort="0.0" lower="-3.14159" upper="3.14159" velocity="0.0"/>
    </joint>
    <link name="RightLower">
        <inertial>
            <origin xyz="0 0 -0.375" rpy="0 0 0"/>
            <mass value="1" />
            <inertia ixx="100" ixy="0" ixz="0" iyy="100" iyz="0" izz="100" />
        </inertial>
        <visual>
            <origin xyz="0 0 -0.375" rpy="0 0 0"/>
            <geometry>
                <box size="0.2 0.2 0.75" />
            </geometry>
            <material name="Cyan">
                <color rgba="0 1.0 1.0 1.0"/>
            </material>
        </visual>
        <collision>
            <origin xyz="0 0 -0.375" rpy="0 0 0"/>
            <geometry>
                <box size="0.2 0.2 0.75" />
            </geometry>
        </collision>
    </link>
</robot>